{"levelname": "ERROR", "asctime": "2017-10-05 18:29:40,528", "message": "Traceback (most recent call last):\n  File \"/home/arun/test/project/test_env/local/lib/python2.7/site-packages/rest_framework/views.py\", line 486, in dispatch\n    response = handler(request, *args, **kwargs)\n  File \"/home/arun/test/project/base_project/src/idcard/views/idcardview.py\", line 25, in create\n    print user\n  File \"/home/arun/test/project/test_env/local/lib/python2.7/site-packages/django/http/response.py\", line 314, in serialize\n    return self.serialize_headers() + b'\\r\\n\\r\\n' + self.content\n  File \"/home/arun/test/project/test_env/local/lib/python2.7/site-packages/django/template/response.py\", line 129, in content\n    'The response content must be rendered before it can be accessed.'\nContentNotRenderedError: The response content must be rendered before it can be accessed.\n", "exc_info": "Traceback (most recent call last):\n  File \"/home/arun/test/project/test_env/local/lib/python2.7/site-packages/rest_framework/views.py\", line 486, in dispatch\n    response = handler(request, *args, **kwargs)\n  File \"/home/arun/test/project/base_project/src/idcard/views/idcardview.py\", line 25, in create\n    print user\n  File \"/home/arun/test/project/test_env/local/lib/python2.7/site-packages/django/http/response.py\", line 314, in serialize\n    return self.serialize_headers() + b'\\r\\n\\r\\n' + self.content\n  File \"/home/arun/test/project/test_env/local/lib/python2.7/site-packages/django/template/response.py\", line 129, in content\n    'The response content must be rendered before it can be accessed.'\nContentNotRenderedError: The response content must be rendered before it can be accessed."}
{"levelname": "ERROR", "asctime": "2017-10-05 18:31:25,427", "message": "Traceback (most recent call last):\n  File \"/home/arun/test/project/test_env/local/lib/python2.7/site-packages/rest_framework/views.py\", line 486, in dispatch\n    response = handler(request, *args, **kwargs)\n  File \"/home/arun/test/project/base_project/src/idcard/views/idcardview.py\", line 30, in create\n    print user\n  File \"/home/arun/test/project/test_env/local/lib/python2.7/site-packages/django/http/response.py\", line 314, in serialize\n    return self.serialize_headers() + b'\\r\\n\\r\\n' + self.content\n  File \"/home/arun/test/project/test_env/local/lib/python2.7/site-packages/django/template/response.py\", line 129, in content\n    'The response content must be rendered before it can be accessed.'\nContentNotRenderedError: The response content must be rendered before it can be accessed.\n", "exc_info": "Traceback (most recent call last):\n  File \"/home/arun/test/project/test_env/local/lib/python2.7/site-packages/rest_framework/views.py\", line 486, in dispatch\n    response = handler(request, *args, **kwargs)\n  File \"/home/arun/test/project/base_project/src/idcard/views/idcardview.py\", line 30, in create\n    print user\n  File \"/home/arun/test/project/test_env/local/lib/python2.7/site-packages/django/http/response.py\", line 314, in serialize\n    return self.serialize_headers() + b'\\r\\n\\r\\n' + self.content\n  File \"/home/arun/test/project/test_env/local/lib/python2.7/site-packages/django/template/response.py\", line 129, in content\n    'The response content must be rendered before it can be accessed.'\nContentNotRenderedError: The response content must be rendered before it can be accessed."}
{"levelname": "ERROR", "asctime": "2017-10-05 18:32:09,474", "message": "Traceback (most recent call last):\n  File \"/home/arun/test/project/test_env/local/lib/python2.7/site-packages/rest_framework/views.py\", line 486, in dispatch\n    response = handler(request, *args, **kwargs)\n  File \"/home/arun/test/project/base_project/src/idcard/views/idcardview.py\", line 31, in create\n    print user\n  File \"/home/arun/test/project/test_env/local/lib/python2.7/site-packages/django/http/response.py\", line 314, in serialize\n    return self.serialize_headers() + b'\\r\\n\\r\\n' + self.content\n  File \"/home/arun/test/project/test_env/local/lib/python2.7/site-packages/django/template/response.py\", line 129, in content\n    'The response content must be rendered before it can be accessed.'\nContentNotRenderedError: The response content must be rendered before it can be accessed.\n", "exc_info": "Traceback (most recent call last):\n  File \"/home/arun/test/project/test_env/local/lib/python2.7/site-packages/rest_framework/views.py\", line 486, in dispatch\n    response = handler(request, *args, **kwargs)\n  File \"/home/arun/test/project/base_project/src/idcard/views/idcardview.py\", line 31, in create\n    print user\n  File \"/home/arun/test/project/test_env/local/lib/python2.7/site-packages/django/http/response.py\", line 314, in serialize\n    return self.serialize_headers() + b'\\r\\n\\r\\n' + self.content\n  File \"/home/arun/test/project/test_env/local/lib/python2.7/site-packages/django/template/response.py\", line 129, in content\n    'The response content must be rendered before it can be accessed.'\nContentNotRenderedError: The response content must be rendered before it can be accessed."}
{"levelname": "ERROR", "asctime": "2017-10-05 18:32:50,727", "message": "Traceback (most recent call last):\n  File \"/home/arun/test/project/test_env/local/lib/python2.7/site-packages/rest_framework/views.py\", line 486, in dispatch\n    response = handler(request, *args, **kwargs)\n  File \"/home/arun/test/project/base_project/src/idcard/views/idcardview.py\", line 31, in create\n    print user\n  File \"/home/arun/test/project/test_env/local/lib/python2.7/site-packages/django/http/response.py\", line 314, in serialize\n    return self.serialize_headers() + b'\\r\\n\\r\\n' + self.content\n  File \"/home/arun/test/project/test_env/local/lib/python2.7/site-packages/django/template/response.py\", line 129, in content\n    'The response content must be rendered before it can be accessed.'\nContentNotRenderedError: The response content must be rendered before it can be accessed.\n", "exc_info": "Traceback (most recent call last):\n  File \"/home/arun/test/project/test_env/local/lib/python2.7/site-packages/rest_framework/views.py\", line 486, in dispatch\n    response = handler(request, *args, **kwargs)\n  File \"/home/arun/test/project/base_project/src/idcard/views/idcardview.py\", line 31, in create\n    print user\n  File \"/home/arun/test/project/test_env/local/lib/python2.7/site-packages/django/http/response.py\", line 314, in serialize\n    return self.serialize_headers() + b'\\r\\n\\r\\n' + self.content\n  File \"/home/arun/test/project/test_env/local/lib/python2.7/site-packages/django/template/response.py\", line 129, in content\n    'The response content must be rendered before it can be accessed.'\nContentNotRenderedError: The response content must be rendered before it can be accessed."}
{"levelname": "ERROR", "asctime": "2017-10-05 18:32:52,613", "message": "Traceback (most recent call last):\n  File \"/home/arun/test/project/test_env/local/lib/python2.7/site-packages/rest_framework/views.py\", line 486, in dispatch\n    response = handler(request, *args, **kwargs)\n  File \"/home/arun/test/project/base_project/src/idcard/views/idcardview.py\", line 31, in create\n    print user\n  File \"/home/arun/test/project/test_env/local/lib/python2.7/site-packages/django/http/response.py\", line 314, in serialize\n    return self.serialize_headers() + b'\\r\\n\\r\\n' + self.content\n  File \"/home/arun/test/project/test_env/local/lib/python2.7/site-packages/django/template/response.py\", line 129, in content\n    'The response content must be rendered before it can be accessed.'\nContentNotRenderedError: The response content must be rendered before it can be accessed.\n", "exc_info": "Traceback (most recent call last):\n  File \"/home/arun/test/project/test_env/local/lib/python2.7/site-packages/rest_framework/views.py\", line 486, in dispatch\n    response = handler(request, *args, **kwargs)\n  File \"/home/arun/test/project/base_project/src/idcard/views/idcardview.py\", line 31, in create\n    print user\n  File \"/home/arun/test/project/test_env/local/lib/python2.7/site-packages/django/http/response.py\", line 314, in serialize\n    return self.serialize_headers() + b'\\r\\n\\r\\n' + self.content\n  File \"/home/arun/test/project/test_env/local/lib/python2.7/site-packages/django/template/response.py\", line 129, in content\n    'The response content must be rendered before it can be accessed.'\nContentNotRenderedError: The response content must be rendered before it can be accessed."}
{"levelname": "ERROR", "asctime": "2017-10-05 18:33:20,102", "message": "Traceback (most recent call last):\n  File \"/home/arun/test/project/test_env/local/lib/python2.7/site-packages/rest_framework/views.py\", line 486, in dispatch\n    response = handler(request, *args, **kwargs)\n  File \"/home/arun/test/project/base_project/src/idcard/views/idcardview.py\", line 31, in create\n    print users\n  File \"/home/arun/test/project/test_env/local/lib/python2.7/site-packages/django/http/response.py\", line 314, in serialize\n    return self.serialize_headers() + b'\\r\\n\\r\\n' + self.content\n  File \"/home/arun/test/project/test_env/local/lib/python2.7/site-packages/django/template/response.py\", line 129, in content\n    'The response content must be rendered before it can be accessed.'\nContentNotRenderedError: The response content must be rendered before it can be accessed.\n", "exc_info": "Traceback (most recent call last):\n  File \"/home/arun/test/project/test_env/local/lib/python2.7/site-packages/rest_framework/views.py\", line 486, in dispatch\n    response = handler(request, *args, **kwargs)\n  File \"/home/arun/test/project/base_project/src/idcard/views/idcardview.py\", line 31, in create\n    print users\n  File \"/home/arun/test/project/test_env/local/lib/python2.7/site-packages/django/http/response.py\", line 314, in serialize\n    return self.serialize_headers() + b'\\r\\n\\r\\n' + self.content\n  File \"/home/arun/test/project/test_env/local/lib/python2.7/site-packages/django/template/response.py\", line 129, in content\n    'The response content must be rendered before it can be accessed.'\nContentNotRenderedError: The response content must be rendered before it can be accessed."}
{"levelname": "ERROR", "asctime": "2017-10-06 17:48:33,007", "message": "Internal Server Error: /id/", "exc_info": "Traceback (most recent call last):\n  File \"/home/arun/test/project/test_env/local/lib/python2.7/site-packages/django/core/handlers/exception.py\", line 41, in inner\n    response = get_response(request)\n  File \"/home/arun/test/project/test_env/local/lib/python2.7/site-packages/django/core/handlers/base.py\", line 217, in _get_response\n    response = self.process_exception_by_middleware(e, request)\n  File \"/home/arun/test/project/test_env/local/lib/python2.7/site-packages/django/core/handlers/base.py\", line 215, in _get_response\n    response = response.render()\n  File \"/home/arun/test/project/test_env/local/lib/python2.7/site-packages/django/template/response.py\", line 107, in render\n    self.content = self.rendered_content\n  File \"/home/arun/test/project/test_env/local/lib/python2.7/site-packages/rest_framework/response.py\", line 72, in rendered_content\n    ret = renderer.render(self.data, accepted_media_type, context)\n  File \"/home/arun/test/project/test_env/local/lib/python2.7/site-packages/rest_framework/renderers.py\", line 105, in render\n    separators=separators\n  File \"/usr/lib/python2.7/json/__init__.py\", line 251, in dumps\n    sort_keys=sort_keys, **kw).encode(obj)\n  File \"/usr/lib/python2.7/json/encoder.py\", line 207, in encode\n    chunks = self.iterencode(o, _one_shot=True)\n  File \"/usr/lib/python2.7/json/encoder.py\", line 270, in iterencode\n    return _iterencode(o, 0)\n  File \"/home/arun/test/project/test_env/local/lib/python2.7/site-packages/rest_framework/utils/encoders.py\", line 70, in default\n    return super(JSONEncoder, self).default(obj)\n  File \"/usr/lib/python2.7/json/encoder.py\", line 184, in default\n    raise TypeError(repr(o) + \" is not JSON serializable\")\nTypeError: <Response status_code=200, \"text/html; charset=utf-8\"> is not JSON serializable", "status_code": 500, "request": "<WSGIRequest: POST '/id/'>"}
{"levelname": "ERROR", "asctime": "2017-10-06 17:51:15,923", "message": "Internal Server Error: /id/", "exc_info": "Traceback (most recent call last):\n  File \"/home/arun/test/project/test_env/local/lib/python2.7/site-packages/django/core/handlers/exception.py\", line 41, in inner\n    response = get_response(request)\n  File \"/home/arun/test/project/test_env/local/lib/python2.7/site-packages/django/core/handlers/base.py\", line 217, in _get_response\n    response = self.process_exception_by_middleware(e, request)\n  File \"/home/arun/test/project/test_env/local/lib/python2.7/site-packages/django/core/handlers/base.py\", line 215, in _get_response\n    response = response.render()\n  File \"/home/arun/test/project/test_env/local/lib/python2.7/site-packages/django/template/response.py\", line 107, in render\n    self.content = self.rendered_content\n  File \"/home/arun/test/project/test_env/local/lib/python2.7/site-packages/rest_framework/response.py\", line 72, in rendered_content\n    ret = renderer.render(self.data, accepted_media_type, context)\n  File \"/home/arun/test/project/test_env/local/lib/python2.7/site-packages/rest_framework/renderers.py\", line 105, in render\n    separators=separators\n  File \"/usr/lib/python2.7/json/__init__.py\", line 251, in dumps\n    sort_keys=sort_keys, **kw).encode(obj)\n  File \"/usr/lib/python2.7/json/encoder.py\", line 207, in encode\n    chunks = self.iterencode(o, _one_shot=True)\n  File \"/usr/lib/python2.7/json/encoder.py\", line 270, in iterencode\n    return _iterencode(o, 0)\n  File \"/home/arun/test/project/test_env/local/lib/python2.7/site-packages/rest_framework/utils/encoders.py\", line 70, in default\n    return super(JSONEncoder, self).default(obj)\n  File \"/usr/lib/python2.7/json/encoder.py\", line 184, in default\n    raise TypeError(repr(o) + \" is not JSON serializable\")\nTypeError: <Response status_code=200, \"text/html; charset=utf-8\"> is not JSON serializable", "status_code": 500, "request": "<WSGIRequest: POST '/id/'>"}
{"levelname": "ERROR", "asctime": "2017-10-06 18:16:34,986", "message": "Traceback (most recent call last):\n  File \"/home/arun/test/project/test_env/local/lib/python2.7/site-packages/rest_framework/views.py\", line 486, in dispatch\n    response = handler(request, *args, **kwargs)\n  File \"/home/arun/test/project/base_project/src/idcard/views/idcardview.py\", line 20, in create\n    ProfilePic = request.data.pop('ProfilePic', None)\n  File \"/home/arun/test/project/test_env/local/lib/python2.7/site-packages/rest_framework/request.py\", line 381, in __getattribute__\n    return super(Request, self).__getattribute__(attr)\n  File \"/home/arun/test/project/test_env/local/lib/python2.7/site-packages/rest_framework/request.py\", line 186, in data\n    self._load_data_and_files()\n  File \"/home/arun/test/project/test_env/local/lib/python2.7/site-packages/rest_framework/request.py\", line 246, in _load_data_and_files\n    self._data, self._files = self._parse()\n  File \"/home/arun/test/project/test_env/local/lib/python2.7/site-packages/rest_framework/request.py\", line 319, in _parse\n    parsed = parser.parse(stream, media_type, self.parser_context)\n  File \"/home/arun/test/project/test_env/local/lib/python2.7/site-packages/rest_framework/parsers.py\", line 68, in parse\n    raise ParseError('JSON parse error - %s' % six.text_type(exc))\nParseError: JSON parse error - Invalid control character at: line 12 column 19 (char 314)\n", "exc_info": "Traceback (most recent call last):\n  File \"/home/arun/test/project/test_env/local/lib/python2.7/site-packages/rest_framework/views.py\", line 486, in dispatch\n    response = handler(request, *args, **kwargs)\n  File \"/home/arun/test/project/base_project/src/idcard/views/idcardview.py\", line 20, in create\n    ProfilePic = request.data.pop('ProfilePic', None)\n  File \"/home/arun/test/project/test_env/local/lib/python2.7/site-packages/rest_framework/request.py\", line 381, in __getattribute__\n    return super(Request, self).__getattribute__(attr)\n  File \"/home/arun/test/project/test_env/local/lib/python2.7/site-packages/rest_framework/request.py\", line 186, in data\n    self._load_data_and_files()\n  File \"/home/arun/test/project/test_env/local/lib/python2.7/site-packages/rest_framework/request.py\", line 246, in _load_data_and_files\n    self._data, self._files = self._parse()\n  File \"/home/arun/test/project/test_env/local/lib/python2.7/site-packages/rest_framework/request.py\", line 319, in _parse\n    parsed = parser.parse(stream, media_type, self.parser_context)\n  File \"/home/arun/test/project/test_env/local/lib/python2.7/site-packages/rest_framework/parsers.py\", line 68, in parse\n    raise ParseError('JSON parse error - %s' % six.text_type(exc))\nParseError: JSON parse error - Invalid control character at: line 12 column 19 (char 314)"}
{"levelname": "ERROR", "asctime": "2017-10-06 18:22:29,226", "message": "Traceback (most recent call last):\n  File \"/home/arun/test/project/test_env/local/lib/python2.7/site-packages/rest_framework/views.py\", line 486, in dispatch\n    response = handler(request, *args, **kwargs)\n  File \"/home/arun/test/project/base_project/src/idcard/views/idcardview.py\", line 24, in create\n    request.data['ProfilePic'] = upload_to_s3from_string(path, file_name, base64.b64decode(ProfilePic))\n  File \"/usr/lib/python2.7/base64.py\", line 78, in b64decode\n    raise TypeError(msg)\nTypeError: Incorrect padding\n", "exc_info": "Traceback (most recent call last):\n  File \"/home/arun/test/project/test_env/local/lib/python2.7/site-packages/rest_framework/views.py\", line 486, in dispatch\n    response = handler(request, *args, **kwargs)\n  File \"/home/arun/test/project/base_project/src/idcard/views/idcardview.py\", line 24, in create\n    request.data['ProfilePic'] = upload_to_s3from_string(path, file_name, base64.b64decode(ProfilePic))\n  File \"/usr/lib/python2.7/base64.py\", line 78, in b64decode\n    raise TypeError(msg)\nTypeError: Incorrect padding"}
{"levelname": "ERROR", "asctime": "2017-10-06 18:22:29,305", "message": "Internal Server Error: /id/", "exc_info": "Traceback (most recent call last):\n  File \"/home/arun/test/project/test_env/local/lib/python2.7/site-packages/django/core/handlers/exception.py\", line 41, in inner\n    response = get_response(request)\n  File \"/home/arun/test/project/test_env/local/lib/python2.7/site-packages/django/core/handlers/base.py\", line 217, in _get_response\n    response = self.process_exception_by_middleware(e, request)\n  File \"/home/arun/test/project/test_env/local/lib/python2.7/site-packages/django/core/handlers/base.py\", line 215, in _get_response\n    response = response.render()\n  File \"/home/arun/test/project/test_env/local/lib/python2.7/site-packages/django/template/response.py\", line 107, in render\n    self.content = self.rendered_content\n  File \"/home/arun/test/project/test_env/local/lib/python2.7/site-packages/rest_framework/response.py\", line 72, in rendered_content\n    ret = renderer.render(self.data, accepted_media_type, context)\n  File \"/home/arun/test/project/test_env/local/lib/python2.7/site-packages/rest_framework/renderers.py\", line 105, in render\n    separators=separators\n  File \"/usr/lib/python2.7/json/__init__.py\", line 251, in dumps\n    sort_keys=sort_keys, **kw).encode(obj)\n  File \"/usr/lib/python2.7/json/encoder.py\", line 207, in encode\n    chunks = self.iterencode(o, _one_shot=True)\n  File \"/usr/lib/python2.7/json/encoder.py\", line 270, in iterencode\n    return _iterencode(o, 0)\n  File \"/home/arun/test/project/test_env/local/lib/python2.7/site-packages/rest_framework/utils/encoders.py\", line 70, in default\n    return super(JSONEncoder, self).default(obj)\n  File \"/usr/lib/python2.7/json/encoder.py\", line 184, in default\n    raise TypeError(repr(o) + \" is not JSON serializable\")\nTypeError: Error('Incorrect padding',) is not JSON serializable", "status_code": 500, "request": "<WSGIRequest: POST '/id/'>"}
{"levelname": "ERROR", "asctime": "2017-10-06 18:23:24,050", "message": "Traceback (most recent call last):\n  File \"/home/arun/test/project/test_env/local/lib/python2.7/site-packages/rest_framework/views.py\", line 486, in dispatch\n    response = handler(request, *args, **kwargs)\n  File \"/home/arun/test/project/base_project/src/idcard/views/idcardview.py\", line 24, in create\n    request.data['ProfilePic'] = upload_to_s3from_string(path, file_name, base64.b64decode(ProfilePic))\n  File \"/usr/lib/python2.7/base64.py\", line 78, in b64decode\n    raise TypeError(msg)\nTypeError: Incorrect padding\n", "exc_info": "Traceback (most recent call last):\n  File \"/home/arun/test/project/test_env/local/lib/python2.7/site-packages/rest_framework/views.py\", line 486, in dispatch\n    response = handler(request, *args, **kwargs)\n  File \"/home/arun/test/project/base_project/src/idcard/views/idcardview.py\", line 24, in create\n    request.data['ProfilePic'] = upload_to_s3from_string(path, file_name, base64.b64decode(ProfilePic))\n  File \"/usr/lib/python2.7/base64.py\", line 78, in b64decode\n    raise TypeError(msg)\nTypeError: Incorrect padding"}
{"levelname": "ERROR", "asctime": "2017-10-06 18:23:24,053", "message": "Internal Server Error: /id/", "exc_info": "Traceback (most recent call last):\n  File \"/home/arun/test/project/test_env/local/lib/python2.7/site-packages/django/core/handlers/exception.py\", line 41, in inner\n    response = get_response(request)\n  File \"/home/arun/test/project/test_env/local/lib/python2.7/site-packages/django/core/handlers/base.py\", line 217, in _get_response\n    response = self.process_exception_by_middleware(e, request)\n  File \"/home/arun/test/project/test_env/local/lib/python2.7/site-packages/django/core/handlers/base.py\", line 215, in _get_response\n    response = response.render()\n  File \"/home/arun/test/project/test_env/local/lib/python2.7/site-packages/django/template/response.py\", line 107, in render\n    self.content = self.rendered_content\n  File \"/home/arun/test/project/test_env/local/lib/python2.7/site-packages/rest_framework/response.py\", line 72, in rendered_content\n    ret = renderer.render(self.data, accepted_media_type, context)\n  File \"/home/arun/test/project/test_env/local/lib/python2.7/site-packages/rest_framework/renderers.py\", line 105, in render\n    separators=separators\n  File \"/usr/lib/python2.7/json/__init__.py\", line 251, in dumps\n    sort_keys=sort_keys, **kw).encode(obj)\n  File \"/usr/lib/python2.7/json/encoder.py\", line 207, in encode\n    chunks = self.iterencode(o, _one_shot=True)\n  File \"/usr/lib/python2.7/json/encoder.py\", line 270, in iterencode\n    return _iterencode(o, 0)\n  File \"/home/arun/test/project/test_env/local/lib/python2.7/site-packages/rest_framework/utils/encoders.py\", line 70, in default\n    return super(JSONEncoder, self).default(obj)\n  File \"/usr/lib/python2.7/json/encoder.py\", line 184, in default\n    raise TypeError(repr(o) + \" is not JSON serializable\")\nTypeError: Error('Incorrect padding',) is not JSON serializable", "status_code": 500, "request": "<WSGIRequest: POST '/id/'>"}
{"levelname": "ERROR", "asctime": "2017-10-06 18:23:25,795", "message": "Traceback (most recent call last):\n  File \"/home/arun/test/project/test_env/local/lib/python2.7/site-packages/rest_framework/views.py\", line 486, in dispatch\n    response = handler(request, *args, **kwargs)\n  File \"/home/arun/test/project/base_project/src/idcard/views/idcardview.py\", line 24, in create\n    request.data['ProfilePic'] = upload_to_s3from_string(path, file_name, base64.b64decode(ProfilePic))\n  File \"/usr/lib/python2.7/base64.py\", line 78, in b64decode\n    raise TypeError(msg)\nTypeError: Incorrect padding\n", "exc_info": "Traceback (most recent call last):\n  File \"/home/arun/test/project/test_env/local/lib/python2.7/site-packages/rest_framework/views.py\", line 486, in dispatch\n    response = handler(request, *args, **kwargs)\n  File \"/home/arun/test/project/base_project/src/idcard/views/idcardview.py\", line 24, in create\n    request.data['ProfilePic'] = upload_to_s3from_string(path, file_name, base64.b64decode(ProfilePic))\n  File \"/usr/lib/python2.7/base64.py\", line 78, in b64decode\n    raise TypeError(msg)\nTypeError: Incorrect padding"}
{"levelname": "ERROR", "asctime": "2017-10-06 18:23:25,798", "message": "Internal Server Error: /id/", "exc_info": "Traceback (most recent call last):\n  File \"/home/arun/test/project/test_env/local/lib/python2.7/site-packages/django/core/handlers/exception.py\", line 41, in inner\n    response = get_response(request)\n  File \"/home/arun/test/project/test_env/local/lib/python2.7/site-packages/django/core/handlers/base.py\", line 217, in _get_response\n    response = self.process_exception_by_middleware(e, request)\n  File \"/home/arun/test/project/test_env/local/lib/python2.7/site-packages/django/core/handlers/base.py\", line 215, in _get_response\n    response = response.render()\n  File \"/home/arun/test/project/test_env/local/lib/python2.7/site-packages/django/template/response.py\", line 107, in render\n    self.content = self.rendered_content\n  File \"/home/arun/test/project/test_env/local/lib/python2.7/site-packages/rest_framework/response.py\", line 72, in rendered_content\n    ret = renderer.render(self.data, accepted_media_type, context)\n  File \"/home/arun/test/project/test_env/local/lib/python2.7/site-packages/rest_framework/renderers.py\", line 105, in render\n    separators=separators\n  File \"/usr/lib/python2.7/json/__init__.py\", line 251, in dumps\n    sort_keys=sort_keys, **kw).encode(obj)\n  File \"/usr/lib/python2.7/json/encoder.py\", line 207, in encode\n    chunks = self.iterencode(o, _one_shot=True)\n  File \"/usr/lib/python2.7/json/encoder.py\", line 270, in iterencode\n    return _iterencode(o, 0)\n  File \"/home/arun/test/project/test_env/local/lib/python2.7/site-packages/rest_framework/utils/encoders.py\", line 70, in default\n    return super(JSONEncoder, self).default(obj)\n  File \"/usr/lib/python2.7/json/encoder.py\", line 184, in default\n    raise TypeError(repr(o) + \" is not JSON serializable\")\nTypeError: Error('Incorrect padding',) is not JSON serializable", "status_code": 500, "request": "<WSGIRequest: POST '/id/'>"}
{"levelname": "ERROR", "asctime": "2017-10-06 18:23:27,535", "message": "Traceback (most recent call last):\n  File \"/home/arun/test/project/test_env/local/lib/python2.7/site-packages/rest_framework/views.py\", line 486, in dispatch\n    response = handler(request, *args, **kwargs)\n  File \"/home/arun/test/project/base_project/src/idcard/views/idcardview.py\", line 24, in create\n    request.data['ProfilePic'] = upload_to_s3from_string(path, file_name, base64.b64decode(ProfilePic))\n  File \"/usr/lib/python2.7/base64.py\", line 78, in b64decode\n    raise TypeError(msg)\nTypeError: Incorrect padding\n", "exc_info": "Traceback (most recent call last):\n  File \"/home/arun/test/project/test_env/local/lib/python2.7/site-packages/rest_framework/views.py\", line 486, in dispatch\n    response = handler(request, *args, **kwargs)\n  File \"/home/arun/test/project/base_project/src/idcard/views/idcardview.py\", line 24, in create\n    request.data['ProfilePic'] = upload_to_s3from_string(path, file_name, base64.b64decode(ProfilePic))\n  File \"/usr/lib/python2.7/base64.py\", line 78, in b64decode\n    raise TypeError(msg)\nTypeError: Incorrect padding"}
{"levelname": "ERROR", "asctime": "2017-10-06 18:23:27,538", "message": "Internal Server Error: /id/", "exc_info": "Traceback (most recent call last):\n  File \"/home/arun/test/project/test_env/local/lib/python2.7/site-packages/django/core/handlers/exception.py\", line 41, in inner\n    response = get_response(request)\n  File \"/home/arun/test/project/test_env/local/lib/python2.7/site-packages/django/core/handlers/base.py\", line 217, in _get_response\n    response = self.process_exception_by_middleware(e, request)\n  File \"/home/arun/test/project/test_env/local/lib/python2.7/site-packages/django/core/handlers/base.py\", line 215, in _get_response\n    response = response.render()\n  File \"/home/arun/test/project/test_env/local/lib/python2.7/site-packages/django/template/response.py\", line 107, in render\n    self.content = self.rendered_content\n  File \"/home/arun/test/project/test_env/local/lib/python2.7/site-packages/rest_framework/response.py\", line 72, in rendered_content\n    ret = renderer.render(self.data, accepted_media_type, context)\n  File \"/home/arun/test/project/test_env/local/lib/python2.7/site-packages/rest_framework/renderers.py\", line 105, in render\n    separators=separators\n  File \"/usr/lib/python2.7/json/__init__.py\", line 251, in dumps\n    sort_keys=sort_keys, **kw).encode(obj)\n  File \"/usr/lib/python2.7/json/encoder.py\", line 207, in encode\n    chunks = self.iterencode(o, _one_shot=True)\n  File \"/usr/lib/python2.7/json/encoder.py\", line 270, in iterencode\n    return _iterencode(o, 0)\n  File \"/home/arun/test/project/test_env/local/lib/python2.7/site-packages/rest_framework/utils/encoders.py\", line 70, in default\n    return super(JSONEncoder, self).default(obj)\n  File \"/usr/lib/python2.7/json/encoder.py\", line 184, in default\n    raise TypeError(repr(o) + \" is not JSON serializable\")\nTypeError: Error('Incorrect padding',) is not JSON serializable", "status_code": 500, "request": "<WSGIRequest: POST '/id/'>"}
{"levelname": "ERROR", "asctime": "2017-10-06 18:23:29,329", "message": "Traceback (most recent call last):\n  File \"/home/arun/test/project/test_env/local/lib/python2.7/site-packages/rest_framework/views.py\", line 486, in dispatch\n    response = handler(request, *args, **kwargs)\n  File \"/home/arun/test/project/base_project/src/idcard/views/idcardview.py\", line 24, in create\n    request.data['ProfilePic'] = upload_to_s3from_string(path, file_name, base64.b64decode(ProfilePic))\n  File \"/usr/lib/python2.7/base64.py\", line 78, in b64decode\n    raise TypeError(msg)\nTypeError: Incorrect padding\n", "exc_info": "Traceback (most recent call last):\n  File \"/home/arun/test/project/test_env/local/lib/python2.7/site-packages/rest_framework/views.py\", line 486, in dispatch\n    response = handler(request, *args, **kwargs)\n  File \"/home/arun/test/project/base_project/src/idcard/views/idcardview.py\", line 24, in create\n    request.data['ProfilePic'] = upload_to_s3from_string(path, file_name, base64.b64decode(ProfilePic))\n  File \"/usr/lib/python2.7/base64.py\", line 78, in b64decode\n    raise TypeError(msg)\nTypeError: Incorrect padding"}
{"levelname": "ERROR", "asctime": "2017-10-06 18:23:29,333", "message": "Internal Server Error: /id/", "exc_info": "Traceback (most recent call last):\n  File \"/home/arun/test/project/test_env/local/lib/python2.7/site-packages/django/core/handlers/exception.py\", line 41, in inner\n    response = get_response(request)\n  File \"/home/arun/test/project/test_env/local/lib/python2.7/site-packages/django/core/handlers/base.py\", line 217, in _get_response\n    response = self.process_exception_by_middleware(e, request)\n  File \"/home/arun/test/project/test_env/local/lib/python2.7/site-packages/django/core/handlers/base.py\", line 215, in _get_response\n    response = response.render()\n  File \"/home/arun/test/project/test_env/local/lib/python2.7/site-packages/django/template/response.py\", line 107, in render\n    self.content = self.rendered_content\n  File \"/home/arun/test/project/test_env/local/lib/python2.7/site-packages/rest_framework/response.py\", line 72, in rendered_content\n    ret = renderer.render(self.data, accepted_media_type, context)\n  File \"/home/arun/test/project/test_env/local/lib/python2.7/site-packages/rest_framework/renderers.py\", line 105, in render\n    separators=separators\n  File \"/usr/lib/python2.7/json/__init__.py\", line 251, in dumps\n    sort_keys=sort_keys, **kw).encode(obj)\n  File \"/usr/lib/python2.7/json/encoder.py\", line 207, in encode\n    chunks = self.iterencode(o, _one_shot=True)\n  File \"/usr/lib/python2.7/json/encoder.py\", line 270, in iterencode\n    return _iterencode(o, 0)\n  File \"/home/arun/test/project/test_env/local/lib/python2.7/site-packages/rest_framework/utils/encoders.py\", line 70, in default\n    return super(JSONEncoder, self).default(obj)\n  File \"/usr/lib/python2.7/json/encoder.py\", line 184, in default\n    raise TypeError(repr(o) + \" is not JSON serializable\")\nTypeError: Error('Incorrect padding',) is not JSON serializable", "status_code": 500, "request": "<WSGIRequest: POST '/id/'>"}
{"levelname": "ERROR", "asctime": "2017-10-06 18:23:30,239", "message": "Traceback (most recent call last):\n  File \"/home/arun/test/project/test_env/local/lib/python2.7/site-packages/rest_framework/views.py\", line 486, in dispatch\n    response = handler(request, *args, **kwargs)\n  File \"/home/arun/test/project/base_project/src/idcard/views/idcardview.py\", line 24, in create\n    request.data['ProfilePic'] = upload_to_s3from_string(path, file_name, base64.b64decode(ProfilePic))\n  File \"/usr/lib/python2.7/base64.py\", line 78, in b64decode\n    raise TypeError(msg)\nTypeError: Incorrect padding\n", "exc_info": "Traceback (most recent call last):\n  File \"/home/arun/test/project/test_env/local/lib/python2.7/site-packages/rest_framework/views.py\", line 486, in dispatch\n    response = handler(request, *args, **kwargs)\n  File \"/home/arun/test/project/base_project/src/idcard/views/idcardview.py\", line 24, in create\n    request.data['ProfilePic'] = upload_to_s3from_string(path, file_name, base64.b64decode(ProfilePic))\n  File \"/usr/lib/python2.7/base64.py\", line 78, in b64decode\n    raise TypeError(msg)\nTypeError: Incorrect padding"}
{"levelname": "ERROR", "asctime": "2017-10-06 18:23:30,245", "message": "Internal Server Error: /id/", "exc_info": "Traceback (most recent call last):\n  File \"/home/arun/test/project/test_env/local/lib/python2.7/site-packages/django/core/handlers/exception.py\", line 41, in inner\n    response = get_response(request)\n  File \"/home/arun/test/project/test_env/local/lib/python2.7/site-packages/django/core/handlers/base.py\", line 217, in _get_response\n    response = self.process_exception_by_middleware(e, request)\n  File \"/home/arun/test/project/test_env/local/lib/python2.7/site-packages/django/core/handlers/base.py\", line 215, in _get_response\n    response = response.render()\n  File \"/home/arun/test/project/test_env/local/lib/python2.7/site-packages/django/template/response.py\", line 107, in render\n    self.content = self.rendered_content\n  File \"/home/arun/test/project/test_env/local/lib/python2.7/site-packages/rest_framework/response.py\", line 72, in rendered_content\n    ret = renderer.render(self.data, accepted_media_type, context)\n  File \"/home/arun/test/project/test_env/local/lib/python2.7/site-packages/rest_framework/renderers.py\", line 105, in render\n    separators=separators\n  File \"/usr/lib/python2.7/json/__init__.py\", line 251, in dumps\n    sort_keys=sort_keys, **kw).encode(obj)\n  File \"/usr/lib/python2.7/json/encoder.py\", line 207, in encode\n    chunks = self.iterencode(o, _one_shot=True)\n  File \"/usr/lib/python2.7/json/encoder.py\", line 270, in iterencode\n    return _iterencode(o, 0)\n  File \"/home/arun/test/project/test_env/local/lib/python2.7/site-packages/rest_framework/utils/encoders.py\", line 70, in default\n    return super(JSONEncoder, self).default(obj)\n  File \"/usr/lib/python2.7/json/encoder.py\", line 184, in default\n    raise TypeError(repr(o) + \" is not JSON serializable\")\nTypeError: Error('Incorrect padding',) is not JSON serializable", "status_code": 500, "request": "<WSGIRequest: POST '/id/'>"}
{"levelname": "ERROR", "asctime": "2017-10-06 18:23:31,424", "message": "Traceback (most recent call last):\n  File \"/home/arun/test/project/test_env/local/lib/python2.7/site-packages/rest_framework/views.py\", line 486, in dispatch\n    response = handler(request, *args, **kwargs)\n  File \"/home/arun/test/project/base_project/src/idcard/views/idcardview.py\", line 24, in create\n    request.data['ProfilePic'] = upload_to_s3from_string(path, file_name, base64.b64decode(ProfilePic))\n  File \"/usr/lib/python2.7/base64.py\", line 78, in b64decode\n    raise TypeError(msg)\nTypeError: Incorrect padding\n", "exc_info": "Traceback (most recent call last):\n  File \"/home/arun/test/project/test_env/local/lib/python2.7/site-packages/rest_framework/views.py\", line 486, in dispatch\n    response = handler(request, *args, **kwargs)\n  File \"/home/arun/test/project/base_project/src/idcard/views/idcardview.py\", line 24, in create\n    request.data['ProfilePic'] = upload_to_s3from_string(path, file_name, base64.b64decode(ProfilePic))\n  File \"/usr/lib/python2.7/base64.py\", line 78, in b64decode\n    raise TypeError(msg)\nTypeError: Incorrect padding"}
{"levelname": "ERROR", "asctime": "2017-10-06 18:23:31,427", "message": "Internal Server Error: /id/", "exc_info": "Traceback (most recent call last):\n  File \"/home/arun/test/project/test_env/local/lib/python2.7/site-packages/django/core/handlers/exception.py\", line 41, in inner\n    response = get_response(request)\n  File \"/home/arun/test/project/test_env/local/lib/python2.7/site-packages/django/core/handlers/base.py\", line 217, in _get_response\n    response = self.process_exception_by_middleware(e, request)\n  File \"/home/arun/test/project/test_env/local/lib/python2.7/site-packages/django/core/handlers/base.py\", line 215, in _get_response\n    response = response.render()\n  File \"/home/arun/test/project/test_env/local/lib/python2.7/site-packages/django/template/response.py\", line 107, in render\n    self.content = self.rendered_content\n  File \"/home/arun/test/project/test_env/local/lib/python2.7/site-packages/rest_framework/response.py\", line 72, in rendered_content\n    ret = renderer.render(self.data, accepted_media_type, context)\n  File \"/home/arun/test/project/test_env/local/lib/python2.7/site-packages/rest_framework/renderers.py\", line 105, in render\n    separators=separators\n  File \"/usr/lib/python2.7/json/__init__.py\", line 251, in dumps\n    sort_keys=sort_keys, **kw).encode(obj)\n  File \"/usr/lib/python2.7/json/encoder.py\", line 207, in encode\n    chunks = self.iterencode(o, _one_shot=True)\n  File \"/usr/lib/python2.7/json/encoder.py\", line 270, in iterencode\n    return _iterencode(o, 0)\n  File \"/home/arun/test/project/test_env/local/lib/python2.7/site-packages/rest_framework/utils/encoders.py\", line 70, in default\n    return super(JSONEncoder, self).default(obj)\n  File \"/usr/lib/python2.7/json/encoder.py\", line 184, in default\n    raise TypeError(repr(o) + \" is not JSON serializable\")\nTypeError: Error('Incorrect padding',) is not JSON serializable", "status_code": 500, "request": "<WSGIRequest: POST '/id/'>"}
{"levelname": "ERROR", "asctime": "2017-10-06 18:24:31,430", "message": "Traceback (most recent call last):\n  File \"/home/arun/test/project/test_env/local/lib/python2.7/site-packages/rest_framework/views.py\", line 486, in dispatch\n    response = handler(request, *args, **kwargs)\n  File \"/home/arun/test/project/base_project/src/idcard/views/idcardview.py\", line 24, in create\n    request.data['ProfilePic'] = upload_to_s3from_string(path, file_name, base64.decodestring(ProfilePic))\n  File \"/usr/lib/python2.7/base64.py\", line 328, in decodestring\n    return binascii.a2b_base64(s)\nError: Incorrect padding\n", "exc_info": "Traceback (most recent call last):\n  File \"/home/arun/test/project/test_env/local/lib/python2.7/site-packages/rest_framework/views.py\", line 486, in dispatch\n    response = handler(request, *args, **kwargs)\n  File \"/home/arun/test/project/base_project/src/idcard/views/idcardview.py\", line 24, in create\n    request.data['ProfilePic'] = upload_to_s3from_string(path, file_name, base64.decodestring(ProfilePic))\n  File \"/usr/lib/python2.7/base64.py\", line 328, in decodestring\n    return binascii.a2b_base64(s)\nError: Incorrect padding"}
{"levelname": "ERROR", "asctime": "2017-10-06 18:27:34,470", "message": "Traceback (most recent call last):\n  File \"/home/arun/test/project/test_env/local/lib/python2.7/site-packages/rest_framework/views.py\", line 486, in dispatch\n    response = handler(request, *args, **kwargs)\n  File \"/home/arun/test/project/base_project/src/idcard/views/idcardview.py\", line 24, in create\n    request.data['ProfilePic'] = upload_to_s3from_string(path, file_name, base64.decodestring(ProfilePic))\n  File \"/usr/lib/python2.7/base64.py\", line 328, in decodestring\n    return binascii.a2b_base64(s)\nError: Incorrect padding\n", "exc_info": "Traceback (most recent call last):\n  File \"/home/arun/test/project/test_env/local/lib/python2.7/site-packages/rest_framework/views.py\", line 486, in dispatch\n    response = handler(request, *args, **kwargs)\n  File \"/home/arun/test/project/base_project/src/idcard/views/idcardview.py\", line 24, in create\n    request.data['ProfilePic'] = upload_to_s3from_string(path, file_name, base64.decodestring(ProfilePic))\n  File \"/usr/lib/python2.7/base64.py\", line 328, in decodestring\n    return binascii.a2b_base64(s)\nError: Incorrect padding"}
{"levelname": "ERROR", "asctime": "2017-10-06 18:47:57,155", "message": "Traceback (most recent call last):\n  File \"/home/arun/test/project/test_env/local/lib/python2.7/site-packages/rest_framework/views.py\", line 486, in dispatch\n    response = handler(request, *args, **kwargs)\n  File \"/home/arun/test/project/base_project/src/idcard/views/idcardview.py\", line 20, in create\n    users = super(IdCardView, self).create(request)\n  File \"/home/arun/test/project/base_project/src/common/libraries/customview.py\", line 15, in create\n    serializer = super(CreateCustomMixin, self).create(request, *args, **kwargs)\n  File \"/home/arun/test/project/test_env/local/lib/python2.7/site-packages/rest_framework/mixins.py\", line 20, in create\n    serializer.is_valid(raise_exception=True)\n  File \"/home/arun/test/project/test_env/local/lib/python2.7/site-packages/rest_framework/serializers.py\", line 245, in is_valid\n    raise ValidationError(self.errors)\nValidationError: {'ProfilePic': [u'Enter a valid URL.']}\n", "exc_info": "Traceback (most recent call last):\n  File \"/home/arun/test/project/test_env/local/lib/python2.7/site-packages/rest_framework/views.py\", line 486, in dispatch\n    response = handler(request, *args, **kwargs)\n  File \"/home/arun/test/project/base_project/src/idcard/views/idcardview.py\", line 20, in create\n    users = super(IdCardView, self).create(request)\n  File \"/home/arun/test/project/base_project/src/common/libraries/customview.py\", line 15, in create\n    serializer = super(CreateCustomMixin, self).create(request, *args, **kwargs)\n  File \"/home/arun/test/project/test_env/local/lib/python2.7/site-packages/rest_framework/mixins.py\", line 20, in create\n    serializer.is_valid(raise_exception=True)\n  File \"/home/arun/test/project/test_env/local/lib/python2.7/site-packages/rest_framework/serializers.py\", line 245, in is_valid\n    raise ValidationError(self.errors)\nValidationError: {'ProfilePic': [u'Enter a valid URL.']}"}
{"levelname": "ERROR", "asctime": "2017-10-06 18:54:18,947", "message": "Traceback (most recent call last):\n  File \"/home/arun/test/project/test_env/local/lib/python2.7/site-packages/rest_framework/views.py\", line 486, in dispatch\n    response = handler(request, *args, **kwargs)\n  File \"/home/arun/test/project/base_project/src/idcard/views/idcardview.py\", line 28, in create\n    user = super(IdCardView, self).update(request)\n  File \"/home/arun/test/project/base_project/src/common/libraries/customview.py\", line 60, in update\n    serializer = super(UpdateCustomMixin, self).update(request, *args, **kwargs)\n  File \"/home/arun/test/project/test_env/local/lib/python2.7/site-packages/rest_framework/mixins.py\", line 67, in update\n    instance = self.get_object()\n  File \"/home/arun/test/project/test_env/local/lib/python2.7/site-packages/rest_framework_mongoengine/generics.py\", line 40, in get_object\n    (self.__class__.__name__, lookup_url_kwarg)\nAssertionError: Expected view IdCardView to be called with a URL keyword argument named \"id\". Fix your URL conf, or set the `.lookup_field` attribute on the view correctly.\n", "exc_info": "Traceback (most recent call last):\n  File \"/home/arun/test/project/test_env/local/lib/python2.7/site-packages/rest_framework/views.py\", line 486, in dispatch\n    response = handler(request, *args, **kwargs)\n  File \"/home/arun/test/project/base_project/src/idcard/views/idcardview.py\", line 28, in create\n    user = super(IdCardView, self).update(request)\n  File \"/home/arun/test/project/base_project/src/common/libraries/customview.py\", line 60, in update\n    serializer = super(UpdateCustomMixin, self).update(request, *args, **kwargs)\n  File \"/home/arun/test/project/test_env/local/lib/python2.7/site-packages/rest_framework/mixins.py\", line 67, in update\n    instance = self.get_object()\n  File \"/home/arun/test/project/test_env/local/lib/python2.7/site-packages/rest_framework_mongoengine/generics.py\", line 40, in get_object\n    (self.__class__.__name__, lookup_url_kwarg)\nAssertionError: Expected view IdCardView to be called with a URL keyword argument named \"id\". Fix your URL conf, or set the `.lookup_field` attribute on the view correctly."}
{"levelname": "ERROR", "asctime": "2017-10-06 18:55:17,319", "message": "Traceback (most recent call last):\n  File \"/home/arun/test/project/test_env/local/lib/python2.7/site-packages/rest_framework/views.py\", line 486, in dispatch\n    response = handler(request, *args, **kwargs)\n  File \"/home/arun/test/project/base_project/src/idcard/views/idcardview.py\", line 28, in create\n    user = super(IdCardView, self).update(users.data['id'], request)\n  File \"/home/arun/test/project/base_project/src/common/libraries/customview.py\", line 60, in update\n    serializer = super(UpdateCustomMixin, self).update(request, *args, **kwargs)\n  File \"/home/arun/test/project/test_env/local/lib/python2.7/site-packages/rest_framework/mixins.py\", line 67, in update\n    instance = self.get_object()\n  File \"/home/arun/test/project/test_env/local/lib/python2.7/site-packages/rest_framework_mongoengine/generics.py\", line 40, in get_object\n    (self.__class__.__name__, lookup_url_kwarg)\nAssertionError: Expected view IdCardView to be called with a URL keyword argument named \"id\". Fix your URL conf, or set the `.lookup_field` attribute on the view correctly.\n", "exc_info": "Traceback (most recent call last):\n  File \"/home/arun/test/project/test_env/local/lib/python2.7/site-packages/rest_framework/views.py\", line 486, in dispatch\n    response = handler(request, *args, **kwargs)\n  File \"/home/arun/test/project/base_project/src/idcard/views/idcardview.py\", line 28, in create\n    user = super(IdCardView, self).update(users.data['id'], request)\n  File \"/home/arun/test/project/base_project/src/common/libraries/customview.py\", line 60, in update\n    serializer = super(UpdateCustomMixin, self).update(request, *args, **kwargs)\n  File \"/home/arun/test/project/test_env/local/lib/python2.7/site-packages/rest_framework/mixins.py\", line 67, in update\n    instance = self.get_object()\n  File \"/home/arun/test/project/test_env/local/lib/python2.7/site-packages/rest_framework_mongoengine/generics.py\", line 40, in get_object\n    (self.__class__.__name__, lookup_url_kwarg)\nAssertionError: Expected view IdCardView to be called with a URL keyword argument named \"id\". Fix your URL conf, or set the `.lookup_field` attribute on the view correctly."}
{"levelname": "ERROR", "asctime": "2017-10-06 19:22:38,445", "message": "Traceback (most recent call last):\n  File \"/home/arun/test/project/test_env/local/lib/python2.7/site-packages/rest_framework/views.py\", line 486, in dispatch\n    response = handler(request, *args, **kwargs)\n  File \"/home/arun/test/project/test_env/local/lib/python2.7/site-packages/rest_framework/decorators.py\", line 52, in handler\n    return func(*args, **kwargs)\n  File \"/home/arun/test/project/base_project/src/idcard/views/generateidcard.py\", line 26, in generate\n    img = generate_idcard(params, id)\n  File \"/home/arun/test/project/base_project/src/idcard/libraries/idcardlib.py\", line 82, in generate_idcard\n    return upload_to_s3(\"\", path+file_name)\n  File \"/home/arun/test/project/base_project/src/common/libraries/helper.py\", line 22, in upload_to_s3\n    k.set_contents_from_filename(filename, policy=S3_PERMISSION)\n  File \"/home/arun/test/project/test_env/local/lib/python2.7/site-packages/boto/s3/key.py\", line 1362, in set_contents_from_filename\n    encrypt_key=encrypt_key)\n  File \"/home/arun/test/project/test_env/local/lib/python2.7/site-packages/boto/s3/key.py\", line 1293, in set_contents_from_file\n    chunked_transfer=chunked_transfer, size=size)\n  File \"/home/arun/test/project/test_env/local/lib/python2.7/site-packages/boto/s3/key.py\", line 750, in send_file\n    chunked_transfer=chunked_transfer, size=size)\n  File \"/home/arun/test/project/test_env/local/lib/python2.7/site-packages/boto/s3/key.py\", line 951, in _send_file_internal\n    query_args=query_args\n  File \"/home/arun/test/project/test_env/local/lib/python2.7/site-packages/boto/s3/connection.py\", line 668, in make_request\n    retry_handler=retry_handler\n  File \"/home/arun/test/project/test_env/local/lib/python2.7/site-packages/boto/connection.py\", line 1071, in make_request\n    retry_handler=retry_handler)\n  File \"/home/arun/test/project/test_env/local/lib/python2.7/site-packages/boto/connection.py\", line 1030, in _mexe\n    raise ex\nSSLError: ('The write operation timed out',)\n", "exc_info": "Traceback (most recent call last):\n  File \"/home/arun/test/project/test_env/local/lib/python2.7/site-packages/rest_framework/views.py\", line 486, in dispatch\n    response = handler(request, *args, **kwargs)\n  File \"/home/arun/test/project/test_env/local/lib/python2.7/site-packages/rest_framework/decorators.py\", line 52, in handler\n    return func(*args, **kwargs)\n  File \"/home/arun/test/project/base_project/src/idcard/views/generateidcard.py\", line 26, in generate\n    img = generate_idcard(params, id)\n  File \"/home/arun/test/project/base_project/src/idcard/libraries/idcardlib.py\", line 82, in generate_idcard\n    return upload_to_s3(\"\", path+file_name)\n  File \"/home/arun/test/project/base_project/src/common/libraries/helper.py\", line 22, in upload_to_s3\n    k.set_contents_from_filename(filename, policy=S3_PERMISSION)\n  File \"/home/arun/test/project/test_env/local/lib/python2.7/site-packages/boto/s3/key.py\", line 1362, in set_contents_from_filename\n    encrypt_key=encrypt_key)\n  File \"/home/arun/test/project/test_env/local/lib/python2.7/site-packages/boto/s3/key.py\", line 1293, in set_contents_from_file\n    chunked_transfer=chunked_transfer, size=size)\n  File \"/home/arun/test/project/test_env/local/lib/python2.7/site-packages/boto/s3/key.py\", line 750, in send_file\n    chunked_transfer=chunked_transfer, size=size)\n  File \"/home/arun/test/project/test_env/local/lib/python2.7/site-packages/boto/s3/key.py\", line 951, in _send_file_internal\n    query_args=query_args\n  File \"/home/arun/test/project/test_env/local/lib/python2.7/site-packages/boto/s3/connection.py\", line 668, in make_request\n    retry_handler=retry_handler\n  File \"/home/arun/test/project/test_env/local/lib/python2.7/site-packages/boto/connection.py\", line 1071, in make_request\n    retry_handler=retry_handler)\n  File \"/home/arun/test/project/test_env/local/lib/python2.7/site-packages/boto/connection.py\", line 1030, in _mexe\n    raise ex\nSSLError: ('The write operation timed out',)"}
{"levelname": "ERROR", "asctime": "2017-10-06 19:32:13,914", "message": "Traceback (most recent call last):\n  File \"/home/arun/test/project/test_env/local/lib/python2.7/site-packages/rest_framework/views.py\", line 486, in dispatch\n    response = handler(request, *args, **kwargs)\n  File \"/home/arun/test/project/test_env/local/lib/python2.7/site-packages/rest_framework/decorators.py\", line 52, in handler\n    return func(*args, **kwargs)\n  File \"/home/arun/test/project/base_project/src/idcard/views/generateidcard.py\", line 26, in generate\n    img = generate_idcard(params, id)\n  File \"/home/arun/test/project/base_project/src/idcard/libraries/idcardlib.py\", line 82, in generate_idcard\n    return upload_to_s3(\"\", path+file_name)\n  File \"/home/arun/test/project/base_project/src/common/libraries/helper.py\", line 16, in upload_to_s3\n    bucket = conn.get_bucket(AWS_STORAGE_BUCKET_NAME)\n  File \"/home/arun/test/project/test_env/local/lib/python2.7/site-packages/boto/s3/connection.py\", line 506, in get_bucket\n    return self.head_bucket(bucket_name, headers=headers)\n  File \"/home/arun/test/project/test_env/local/lib/python2.7/site-packages/boto/s3/connection.py\", line 525, in head_bucket\n    response = self.make_request('HEAD', bucket_name, headers=headers)\n  File \"/home/arun/test/project/test_env/local/lib/python2.7/site-packages/boto/s3/connection.py\", line 668, in make_request\n    retry_handler=retry_handler\n  File \"/home/arun/test/project/test_env/local/lib/python2.7/site-packages/boto/connection.py\", line 1071, in make_request\n    retry_handler=retry_handler)\n  File \"/home/arun/test/project/test_env/local/lib/python2.7/site-packages/boto/connection.py\", line 1030, in _mexe\n    raise ex\ntimeout: timed out\n", "exc_info": "Traceback (most recent call last):\n  File \"/home/arun/test/project/test_env/local/lib/python2.7/site-packages/rest_framework/views.py\", line 486, in dispatch\n    response = handler(request, *args, **kwargs)\n  File \"/home/arun/test/project/test_env/local/lib/python2.7/site-packages/rest_framework/decorators.py\", line 52, in handler\n    return func(*args, **kwargs)\n  File \"/home/arun/test/project/base_project/src/idcard/views/generateidcard.py\", line 26, in generate\n    img = generate_idcard(params, id)\n  File \"/home/arun/test/project/base_project/src/idcard/libraries/idcardlib.py\", line 82, in generate_idcard\n    return upload_to_s3(\"\", path+file_name)\n  File \"/home/arun/test/project/base_project/src/common/libraries/helper.py\", line 16, in upload_to_s3\n    bucket = conn.get_bucket(AWS_STORAGE_BUCKET_NAME)\n  File \"/home/arun/test/project/test_env/local/lib/python2.7/site-packages/boto/s3/connection.py\", line 506, in get_bucket\n    return self.head_bucket(bucket_name, headers=headers)\n  File \"/home/arun/test/project/test_env/local/lib/python2.7/site-packages/boto/s3/connection.py\", line 525, in head_bucket\n    response = self.make_request('HEAD', bucket_name, headers=headers)\n  File \"/home/arun/test/project/test_env/local/lib/python2.7/site-packages/boto/s3/connection.py\", line 668, in make_request\n    retry_handler=retry_handler\n  File \"/home/arun/test/project/test_env/local/lib/python2.7/site-packages/boto/connection.py\", line 1071, in make_request\n    retry_handler=retry_handler)\n  File \"/home/arun/test/project/test_env/local/lib/python2.7/site-packages/boto/connection.py\", line 1030, in _mexe\n    raise ex\ntimeout: timed out"}
{"levelname": "ERROR", "asctime": "2017-10-06 19:57:39,117", "message": "Traceback (most recent call last):\n  File \"/home/arun/test/project/test_env/local/lib/python2.7/site-packages/rest_framework/views.py\", line 486, in dispatch\n    response = handler(request, *args, **kwargs)\n  File \"/home/arun/test/project/test_env/local/lib/python2.7/site-packages/rest_framework/decorators.py\", line 52, in handler\n    return func(*args, **kwargs)\n  File \"/home/arun/test/project/base_project/src/idcard/views/generateidcard.py\", line 18, in generate\n    QR = Requests.post(url=googleurl, data={\"long\": url})\nNameError: global name 'Requests' is not defined\n", "exc_info": "Traceback (most recent call last):\n  File \"/home/arun/test/project/test_env/local/lib/python2.7/site-packages/rest_framework/views.py\", line 486, in dispatch\n    response = handler(request, *args, **kwargs)\n  File \"/home/arun/test/project/test_env/local/lib/python2.7/site-packages/rest_framework/decorators.py\", line 52, in handler\n    return func(*args, **kwargs)\n  File \"/home/arun/test/project/base_project/src/idcard/views/generateidcard.py\", line 18, in generate\n    QR = Requests.post(url=googleurl, data={\"long\": url})\nNameError: global name 'Requests' is not defined"}
{"levelname": "ERROR", "asctime": "2017-10-06 20:05:20,838", "message": "Traceback (most recent call last):\n  File \"/home/arun/test/project/test_env/local/lib/python2.7/site-packages/rest_framework/views.py\", line 486, in dispatch\n    response = handler(request, *args, **kwargs)\n  File \"/home/arun/test/project/test_env/local/lib/python2.7/site-packages/rest_framework/decorators.py\", line 52, in handler\n    return func(*args, **kwargs)\n  File \"/home/arun/test/project/base_project/src/idcard/views/generateidcard.py\", line 22, in generate\n    content = urllib2.urlopen(req).read()\n  File \"/usr/lib/python2.7/urllib2.py\", line 154, in urlopen\n    return opener.open(url, data, timeout)\n  File \"/usr/lib/python2.7/urllib2.py\", line 429, in open\n    response = self._open(req, data)\n  File \"/usr/lib/python2.7/urllib2.py\", line 447, in _open\n    '_open', req)\n  File \"/usr/lib/python2.7/urllib2.py\", line 407, in _call_chain\n    result = func(*args)\n  File \"/usr/lib/python2.7/urllib2.py\", line 1241, in https_open\n    context=self._context)\n  File \"/usr/lib/python2.7/urllib2.py\", line 1195, in do_open\n    h.request(req.get_method(), req.get_selector(), req.data, headers)\n  File \"/usr/lib/python2.7/httplib.py\", line 1057, in request\n    self._send_request(method, url, body, headers)\n  File \"/usr/lib/python2.7/httplib.py\", line 1097, in _send_request\n    self.endheaders(body)\n  File \"/usr/lib/python2.7/httplib.py\", line 1053, in endheaders\n    self._send_output(message_body)\n  File \"/usr/lib/python2.7/httplib.py\", line 901, in _send_output\n    self.send(message_body)\n  File \"/usr/lib/python2.7/httplib.py\", line 873, in send\n    self.sock.sendall(data)\n  File \"/usr/lib/python2.7/ssl.py\", line 743, in sendall\n    v = self.send(data[count:])\nTypeError: unhashable type\n", "exc_info": "Traceback (most recent call last):\n  File \"/home/arun/test/project/test_env/local/lib/python2.7/site-packages/rest_framework/views.py\", line 486, in dispatch\n    response = handler(request, *args, **kwargs)\n  File \"/home/arun/test/project/test_env/local/lib/python2.7/site-packages/rest_framework/decorators.py\", line 52, in handler\n    return func(*args, **kwargs)\n  File \"/home/arun/test/project/base_project/src/idcard/views/generateidcard.py\", line 22, in generate\n    content = urllib2.urlopen(req).read()\n  File \"/usr/lib/python2.7/urllib2.py\", line 154, in urlopen\n    return opener.open(url, data, timeout)\n  File \"/usr/lib/python2.7/urllib2.py\", line 429, in open\n    response = self._open(req, data)\n  File \"/usr/lib/python2.7/urllib2.py\", line 447, in _open\n    '_open', req)\n  File \"/usr/lib/python2.7/urllib2.py\", line 407, in _call_chain\n    result = func(*args)\n  File \"/usr/lib/python2.7/urllib2.py\", line 1241, in https_open\n    context=self._context)\n  File \"/usr/lib/python2.7/urllib2.py\", line 1195, in do_open\n    h.request(req.get_method(), req.get_selector(), req.data, headers)\n  File \"/usr/lib/python2.7/httplib.py\", line 1057, in request\n    self._send_request(method, url, body, headers)\n  File \"/usr/lib/python2.7/httplib.py\", line 1097, in _send_request\n    self.endheaders(body)\n  File \"/usr/lib/python2.7/httplib.py\", line 1053, in endheaders\n    self._send_output(message_body)\n  File \"/usr/lib/python2.7/httplib.py\", line 901, in _send_output\n    self.send(message_body)\n  File \"/usr/lib/python2.7/httplib.py\", line 873, in send\n    self.sock.sendall(data)\n  File \"/usr/lib/python2.7/ssl.py\", line 743, in sendall\n    v = self.send(data[count:])\nTypeError: unhashable type"}
{"levelname": "ERROR", "asctime": "2017-10-06 20:05:39,972", "message": "Traceback (most recent call last):\n  File \"/home/arun/test/project/test_env/local/lib/python2.7/site-packages/rest_framework/views.py\", line 486, in dispatch\n    response = handler(request, *args, **kwargs)\n  File \"/home/arun/test/project/test_env/local/lib/python2.7/site-packages/rest_framework/decorators.py\", line 52, in handler\n    return func(*args, **kwargs)\n  File \"/home/arun/test/project/base_project/src/idcard/views/generateidcard.py\", line 22, in generate\n    content = urllib2.urlopen(req).read()\n  File \"/usr/lib/python2.7/urllib2.py\", line 154, in urlopen\n    return opener.open(url, data, timeout)\n  File \"/usr/lib/python2.7/urllib2.py\", line 429, in open\n    response = self._open(req, data)\n  File \"/usr/lib/python2.7/urllib2.py\", line 447, in _open\n    '_open', req)\n  File \"/usr/lib/python2.7/urllib2.py\", line 407, in _call_chain\n    result = func(*args)\n  File \"/usr/lib/python2.7/urllib2.py\", line 1241, in https_open\n    context=self._context)\n  File \"/usr/lib/python2.7/urllib2.py\", line 1195, in do_open\n    h.request(req.get_method(), req.get_selector(), req.data, headers)\n  File \"/usr/lib/python2.7/httplib.py\", line 1057, in request\n    self._send_request(method, url, body, headers)\n  File \"/usr/lib/python2.7/httplib.py\", line 1097, in _send_request\n    self.endheaders(body)\n  File \"/usr/lib/python2.7/httplib.py\", line 1053, in endheaders\n    self._send_output(message_body)\n  File \"/usr/lib/python2.7/httplib.py\", line 901, in _send_output\n    self.send(message_body)\n  File \"/usr/lib/python2.7/httplib.py\", line 873, in send\n    self.sock.sendall(data)\n  File \"/usr/lib/python2.7/ssl.py\", line 743, in sendall\n    v = self.send(data[count:])\nTypeError: unhashable type\n", "exc_info": "Traceback (most recent call last):\n  File \"/home/arun/test/project/test_env/local/lib/python2.7/site-packages/rest_framework/views.py\", line 486, in dispatch\n    response = handler(request, *args, **kwargs)\n  File \"/home/arun/test/project/test_env/local/lib/python2.7/site-packages/rest_framework/decorators.py\", line 52, in handler\n    return func(*args, **kwargs)\n  File \"/home/arun/test/project/base_project/src/idcard/views/generateidcard.py\", line 22, in generate\n    content = urllib2.urlopen(req).read()\n  File \"/usr/lib/python2.7/urllib2.py\", line 154, in urlopen\n    return opener.open(url, data, timeout)\n  File \"/usr/lib/python2.7/urllib2.py\", line 429, in open\n    response = self._open(req, data)\n  File \"/usr/lib/python2.7/urllib2.py\", line 447, in _open\n    '_open', req)\n  File \"/usr/lib/python2.7/urllib2.py\", line 407, in _call_chain\n    result = func(*args)\n  File \"/usr/lib/python2.7/urllib2.py\", line 1241, in https_open\n    context=self._context)\n  File \"/usr/lib/python2.7/urllib2.py\", line 1195, in do_open\n    h.request(req.get_method(), req.get_selector(), req.data, headers)\n  File \"/usr/lib/python2.7/httplib.py\", line 1057, in request\n    self._send_request(method, url, body, headers)\n  File \"/usr/lib/python2.7/httplib.py\", line 1097, in _send_request\n    self.endheaders(body)\n  File \"/usr/lib/python2.7/httplib.py\", line 1053, in endheaders\n    self._send_output(message_body)\n  File \"/usr/lib/python2.7/httplib.py\", line 901, in _send_output\n    self.send(message_body)\n  File \"/usr/lib/python2.7/httplib.py\", line 873, in send\n    self.sock.sendall(data)\n  File \"/usr/lib/python2.7/ssl.py\", line 743, in sendall\n    v = self.send(data[count:])\nTypeError: unhashable type"}
